Traceback (most recent call last):
  File "/home/joe/25testing/lib/python3.7/site-packages/container_service_extension/client/cse.py", line 370, in cluster_create
    org=org_name)
  File "/home/joe/25testing/lib/python3.7/site-packages/container_service_extension/client/cluster.py", line 118, in create_cluster
    return process_response(response)
  File "/home/joe/25testing/lib/python3.7/site-packages/container_service_extension/client/response_processor.py", line 40, in process_response
    response_to_exception(response)
  File "/home/joe/25testing/lib/python3.7/site-packages/container_service_extension/client/response_processor.py", line 102, in response_to_exception
    raise VcdResponseError(response.status_code, message)
container_service_extension.exceptions.VcdResponseError: Required keys in data have None as value: ['network_name']

